2022-09-21 09:36:16,157 ERROR: Exception on /data [GET] [in /Users/ryancalderone/venv/lib/python3.7/site-packages/flask/app.py:1455]
Traceback (most recent call last):
  File "/Users/ryancalderone/venv/lib/python3.7/site-packages/flask/app.py", line 2070, in wsgi_app
    response = self.full_dispatch_request()
  File "/Users/ryancalderone/venv/lib/python3.7/site-packages/flask/app.py", line 1515, in full_dispatch_request
    rv = self.handle_user_exception(e)
  File "/Users/ryancalderone/venv/lib/python3.7/site-packages/flask/app.py", line 1513, in full_dispatch_request
    rv = self.dispatch_request()
  File "/Users/ryancalderone/venv/lib/python3.7/site-packages/flask/app.py", line 1499, in dispatch_request
    return self.ensure_sync(self.view_functions[rule.endpoint])(**req.view_args)
  File "/Users/ryancalderone/venv/lib/python3.7/site-packages/flask_login/utils.py", line 290, in decorated_view
    return current_app.ensure_sync(func)(*args, **kwargs)
  File "/Users/ryancalderone/HPP/HPP/app/routes.py", line 156, in data
    return render_template('dataEntry.html', output=prediction, form=form)
NameError: name 'form' is not defined
2022-09-21 09:36:27,149 INFO: Hpp startup [in /Users/ryancalderone/HPP/HPP/app/__init__.py:46]
2022-09-21 09:36:51,825 INFO: Hpp startup [in /Users/ryancalderone/HPP/HPP/app/__init__.py:46]
2022-09-21 09:36:57,910 ERROR: Exception on /data [GET] [in /Users/ryancalderone/venv/lib/python3.7/site-packages/flask/app.py:1455]
Traceback (most recent call last):
  File "/Users/ryancalderone/venv/lib/python3.7/site-packages/flask/app.py", line 2070, in wsgi_app
    response = self.full_dispatch_request()
  File "/Users/ryancalderone/venv/lib/python3.7/site-packages/flask/app.py", line 1515, in full_dispatch_request
    rv = self.handle_user_exception(e)
  File "/Users/ryancalderone/venv/lib/python3.7/site-packages/flask/app.py", line 1513, in full_dispatch_request
    rv = self.dispatch_request()
  File "/Users/ryancalderone/venv/lib/python3.7/site-packages/flask/app.py", line 1499, in dispatch_request
    return self.ensure_sync(self.view_functions[rule.endpoint])(**req.view_args)
  File "/Users/ryancalderone/venv/lib/python3.7/site-packages/flask_login/utils.py", line 290, in decorated_view
    return current_app.ensure_sync(func)(*args, **kwargs)
  File "/Users/ryancalderone/HPP/HPP/app/routes.py", line 156, in data
    return render_template('dataEntry.html', output=prediction, form=form)
NameError: name 'form' is not defined
2022-09-21 09:37:06,284 ERROR: Exception on /data [GET] [in /Users/ryancalderone/venv/lib/python3.7/site-packages/flask/app.py:1455]
Traceback (most recent call last):
  File "/Users/ryancalderone/venv/lib/python3.7/site-packages/flask/app.py", line 2070, in wsgi_app
    response = self.full_dispatch_request()
  File "/Users/ryancalderone/venv/lib/python3.7/site-packages/flask/app.py", line 1515, in full_dispatch_request
    rv = self.handle_user_exception(e)
  File "/Users/ryancalderone/venv/lib/python3.7/site-packages/flask/app.py", line 1513, in full_dispatch_request
    rv = self.dispatch_request()
  File "/Users/ryancalderone/venv/lib/python3.7/site-packages/flask/app.py", line 1499, in dispatch_request
    return self.ensure_sync(self.view_functions[rule.endpoint])(**req.view_args)
  File "/Users/ryancalderone/venv/lib/python3.7/site-packages/flask_login/utils.py", line 290, in decorated_view
    return current_app.ensure_sync(func)(*args, **kwargs)
  File "/Users/ryancalderone/HPP/HPP/app/routes.py", line 156, in data
    return render_template('dataEntry.html', output=prediction, form=form)
NameError: name 'form' is not defined
2022-09-21 09:39:11,093 INFO: Hpp startup [in /Users/ryancalderone/HPP/HPP/app/__init__.py:46]
2022-09-21 09:39:18,723 ERROR: Exception on /data [GET] [in /Users/ryancalderone/venv/lib/python3.7/site-packages/flask/app.py:1455]
Traceback (most recent call last):
  File "/Users/ryancalderone/venv/lib/python3.7/site-packages/flask/app.py", line 2070, in wsgi_app
    response = self.full_dispatch_request()
  File "/Users/ryancalderone/venv/lib/python3.7/site-packages/flask/app.py", line 1515, in full_dispatch_request
    rv = self.handle_user_exception(e)
  File "/Users/ryancalderone/venv/lib/python3.7/site-packages/flask/app.py", line 1513, in full_dispatch_request
    rv = self.dispatch_request()
  File "/Users/ryancalderone/venv/lib/python3.7/site-packages/flask/app.py", line 1499, in dispatch_request
    return self.ensure_sync(self.view_functions[rule.endpoint])(**req.view_args)
  File "/Users/ryancalderone/venv/lib/python3.7/site-packages/flask_login/utils.py", line 290, in decorated_view
    return current_app.ensure_sync(func)(*args, **kwargs)
  File "/Users/ryancalderone/HPP/HPP/app/routes.py", line 156, in data
    return render_template('dataEntry.html', output=prediction, form=form)
NameError: name 'form' is not defined
2022-09-21 09:45:11,890 INFO: Hpp startup [in /Users/ryancalderone/HPP/HPP/app/__init__.py:46]
2022-09-21 09:45:19,709 ERROR: Exception on /data [GET] [in /Users/ryancalderone/venv/lib/python3.7/site-packages/flask/app.py:1455]
Traceback (most recent call last):
  File "/Users/ryancalderone/venv/lib/python3.7/site-packages/flask/app.py", line 2070, in wsgi_app
    response = self.full_dispatch_request()
  File "/Users/ryancalderone/venv/lib/python3.7/site-packages/flask/app.py", line 1515, in full_dispatch_request
    rv = self.handle_user_exception(e)
  File "/Users/ryancalderone/venv/lib/python3.7/site-packages/flask/app.py", line 1513, in full_dispatch_request
    rv = self.dispatch_request()
  File "/Users/ryancalderone/venv/lib/python3.7/site-packages/flask/app.py", line 1499, in dispatch_request
    return self.ensure_sync(self.view_functions[rule.endpoint])(**req.view_args)
  File "/Users/ryancalderone/venv/lib/python3.7/site-packages/flask_login/utils.py", line 290, in decorated_view
    return current_app.ensure_sync(func)(*args, **kwargs)
  File "/Users/ryancalderone/HPP/HPP/app/routes.py", line 157, in data
    return render_template('dataEntry.html', output=prediction, form=form)
  File "/Users/ryancalderone/venv/lib/python3.7/site-packages/flask/templating.py", line 150, in render_template
    ctx.app,
  File "/Users/ryancalderone/venv/lib/python3.7/site-packages/flask/templating.py", line 128, in _render
    rv = template.render(context)
  File "/Users/ryancalderone/venv/lib/python3.7/site-packages/jinja2/environment.py", line 1304, in render
    self.environment.handle_exception()
  File "/Users/ryancalderone/venv/lib/python3.7/site-packages/jinja2/environment.py", line 925, in handle_exception
    raise rewrite_traceback_stack(source=source)
  File "/Users/ryancalderone/HPP/HPP/app/templates/dataEntry.html", line 1, in top-level template code
    {% extends "base.html" %}
  File "/Users/ryancalderone/HPP/HPP/app/templates/base.html", line 52, in top-level template code
    {% endif %} {% endwith %} {% block content %}{% endblock %}
  File "/Users/ryancalderone/HPP/HPP/app/templates/dataEntry.html", line 45, in block 'content'
    {{ form.Garage.label }} {{ form.GarageSize() }}
  File "/Users/ryancalderone/venv/lib/python3.7/site-packages/jinja2/utils.py", line 84, in from_obj
    if hasattr(obj, "jinja_pass_arg"):
jinja2.exceptions.UndefinedError: 'app.forms.DataForm object' has no attribute 'GarageSize'
2022-09-21 09:46:36,135 INFO: Hpp startup [in /Users/ryancalderone/HPP/HPP/app/__init__.py:46]
2022-09-21 09:47:35,568 ERROR: Exception on /data [POST] [in /Users/ryancalderone/venv/lib/python3.7/site-packages/flask/app.py:1455]
Traceback (most recent call last):
  File "/Users/ryancalderone/venv/lib/python3.7/site-packages/flask/app.py", line 2070, in wsgi_app
    response = self.full_dispatch_request()
  File "/Users/ryancalderone/venv/lib/python3.7/site-packages/flask/app.py", line 1515, in full_dispatch_request
    rv = self.handle_user_exception(e)
  File "/Users/ryancalderone/venv/lib/python3.7/site-packages/flask/app.py", line 1513, in full_dispatch_request
    rv = self.dispatch_request()
  File "/Users/ryancalderone/venv/lib/python3.7/site-packages/flask/app.py", line 1499, in dispatch_request
    return self.ensure_sync(self.view_functions[rule.endpoint])(**req.view_args)
  File "/Users/ryancalderone/venv/lib/python3.7/site-packages/flask_login/utils.py", line 290, in decorated_view
    return current_app.ensure_sync(func)(*args, **kwargs)
  File "/Users/ryancalderone/HPP/HPP/app/routes.py", line 135, in data
    lin_reg = joblib.load("lin_reg.pkl")
  File "/Users/ryancalderone/venv/lib/python3.7/site-packages/joblib/numpy_pickle.py", line 577, in load
    with open(filename, 'rb') as f:
FileNotFoundError: [Errno 2] No such file or directory: 'lin_reg.pkl'
2022-09-21 09:48:32,089 ERROR: Exception on /data [POST] [in /Users/ryancalderone/venv/lib/python3.7/site-packages/flask/app.py:1455]
Traceback (most recent call last):
  File "/Users/ryancalderone/venv/lib/python3.7/site-packages/flask/app.py", line 2070, in wsgi_app
    response = self.full_dispatch_request()
  File "/Users/ryancalderone/venv/lib/python3.7/site-packages/flask/app.py", line 1515, in full_dispatch_request
    rv = self.handle_user_exception(e)
  File "/Users/ryancalderone/venv/lib/python3.7/site-packages/flask/app.py", line 1513, in full_dispatch_request
    rv = self.dispatch_request()
  File "/Users/ryancalderone/venv/lib/python3.7/site-packages/flask/app.py", line 1499, in dispatch_request
    return self.ensure_sync(self.view_functions[rule.endpoint])(**req.view_args)
  File "/Users/ryancalderone/venv/lib/python3.7/site-packages/flask_login/utils.py", line 290, in decorated_view
    return current_app.ensure_sync(func)(*args, **kwargs)
  File "/Users/ryancalderone/HPP/HPP/app/routes.py", line 135, in data
    lin_reg = joblib.load("lin_reg.pkl")
  File "/Users/ryancalderone/venv/lib/python3.7/site-packages/joblib/numpy_pickle.py", line 577, in load
    with open(filename, 'rb') as f:
FileNotFoundError: [Errno 2] No such file or directory: 'lin_reg.pkl'
2022-09-21 09:50:52,464 INFO: Hpp startup [in /Users/ryancalderone/HPP/HPP/app/__init__.py:46]
