2022-09-17 23:57:09,723 ERROR: Exception on /reset_password_request [POST] [in /Users/ryancalderone/venv/lib/python3.7/site-packages/flask/app.py:1455]
Traceback (most recent call last):
  File "/Users/ryancalderone/venv/lib/python3.7/site-packages/flask/app.py", line 2070, in wsgi_app
    response = self.full_dispatch_request()
  File "/Users/ryancalderone/venv/lib/python3.7/site-packages/flask/app.py", line 1515, in full_dispatch_request
    rv = self.handle_user_exception(e)
  File "/Users/ryancalderone/venv/lib/python3.7/site-packages/flask/app.py", line 1513, in full_dispatch_request
    rv = self.dispatch_request()
  File "/Users/ryancalderone/venv/lib/python3.7/site-packages/flask/app.py", line 1499, in dispatch_request
    return self.ensure_sync(self.view_functions[rule.endpoint])(**req.view_args)
  File "/Users/ryancalderone/HPP/HPP/app/routes.py", line 68, in reset_password_request
    return redirect(url_fro('login'))
NameError: name 'url_fro' is not defined
2022-09-17 23:59:53,574 INFO: Hpp startup [in /Users/ryancalderone/HPP/HPP/app/__init__.py:43]
2022-09-18 00:00:06,277 ERROR: Exception on /reset_password_request [POST] [in /Users/ryancalderone/venv/lib/python3.7/site-packages/flask/app.py:1455]
Traceback (most recent call last):
  File "/Users/ryancalderone/venv/lib/python3.7/site-packages/flask/app.py", line 2070, in wsgi_app
    response = self.full_dispatch_request()
  File "/Users/ryancalderone/venv/lib/python3.7/site-packages/flask/app.py", line 1515, in full_dispatch_request
    rv = self.handle_user_exception(e)
  File "/Users/ryancalderone/venv/lib/python3.7/site-packages/flask/app.py", line 1513, in full_dispatch_request
    rv = self.dispatch_request()
  File "/Users/ryancalderone/venv/lib/python3.7/site-packages/flask/app.py", line 1499, in dispatch_request
    return self.ensure_sync(self.view_functions[rule.endpoint])(**req.view_args)
  File "/Users/ryancalderone/HPP/HPP/app/routes.py", line 68, in reset_password_request
    return redirect(url_fro('login'))
NameError: name 'url_fro' is not defined
2022-09-18 00:01:07,663 INFO: Hpp startup [in /Users/ryancalderone/HPP/HPP/app/__init__.py:43]
2022-09-18 00:01:19,891 ERROR: Exception on /reset_password_request [POST] [in /Users/ryancalderone/venv/lib/python3.7/site-packages/flask/app.py:1455]
Traceback (most recent call last):
  File "/Users/ryancalderone/venv/lib/python3.7/site-packages/flask/app.py", line 2070, in wsgi_app
    response = self.full_dispatch_request()
  File "/Users/ryancalderone/venv/lib/python3.7/site-packages/flask/app.py", line 1515, in full_dispatch_request
    rv = self.handle_user_exception(e)
  File "/Users/ryancalderone/venv/lib/python3.7/site-packages/flask/app.py", line 1513, in full_dispatch_request
    rv = self.dispatch_request()
  File "/Users/ryancalderone/venv/lib/python3.7/site-packages/flask/app.py", line 1499, in dispatch_request
    return self.ensure_sync(self.view_functions[rule.endpoint])(**req.view_args)
  File "/Users/ryancalderone/HPP/HPP/app/routes.py", line 68, in reset_password_request
    return redirect(url_fro('login'))
NameError: name 'url_fro' is not defined
2022-09-18 00:22:16,982 INFO: Hpp startup [in /Users/ryancalderone/HPP/HPP/app/__init__.py:46]
2022-09-18 00:23:45,556 INFO: Hpp startup [in /Users/ryancalderone/HPP/HPP/app/__init__.py:46]
2022-09-18 00:24:53,840 INFO: Hpp startup [in /Users/ryancalderone/HPP/HPP/app/__init__.py:46]
2022-09-18 00:25:21,725 INFO: Hpp startup [in /Users/ryancalderone/HPP/HPP/app/__init__.py:46]
2022-09-18 00:25:35,946 INFO: Hpp startup [in /Users/ryancalderone/HPP/HPP/app/__init__.py:46]
2022-09-18 00:47:45,550 INFO: Hpp startup [in /Users/ryancalderone/HPP/HPP/app/__init__.py:46]
2022-09-18 00:54:08,326 INFO: Hpp startup [in /Users/ryancalderone/HPP/HPP/app/__init__.py:46]
2022-09-18 00:56:00,999 INFO: Hpp startup [in /Users/ryancalderone/HPP/HPP/app/__init__.py:46]
2022-09-18 00:57:08,394 INFO: Hpp startup [in /Users/ryancalderone/HPP/HPP/app/__init__.py:46]
2022-09-18 01:01:11,033 INFO: Hpp startup [in /Users/ryancalderone/HPP/HPP/app/__init__.py:46]
2022-09-18 01:02:19,962 INFO: Hpp startup [in /Users/ryancalderone/HPP/HPP/app/__init__.py:46]
2022-09-18 12:50:37,461 INFO: Hpp startup [in /Users/ryancalderone/HPP/HPP/app/__init__.py:46]
2022-09-19 11:19:26,053 INFO: Hpp startup [in /Users/ryancalderone/HPP/HPP copy 3/app/__init__.py:46]
2022-09-19 11:20:29,461 ERROR: Exception on /reset_password_request [POST] [in /Users/ryancalderone/venv/lib/python3.7/site-packages/flask/app.py:1455]
Traceback (most recent call last):
  File "/Users/ryancalderone/venv/lib/python3.7/site-packages/flask/app.py", line 2070, in wsgi_app
    response = self.full_dispatch_request()
  File "/Users/ryancalderone/venv/lib/python3.7/site-packages/flask/app.py", line 1515, in full_dispatch_request
    rv = self.handle_user_exception(e)
  File "/Users/ryancalderone/venv/lib/python3.7/site-packages/flask/app.py", line 1513, in full_dispatch_request
    rv = self.dispatch_request()
  File "/Users/ryancalderone/venv/lib/python3.7/site-packages/flask/app.py", line 1499, in dispatch_request
    return self.ensure_sync(self.view_functions[rule.endpoint])(**req.view_args)
  File "/Users/ryancalderone/HPP/HPP copy 3/app/routes.py", line 68, in reset_password_request
    return redirect(url_fro('login'))
NameError: name 'url_fro' is not defined
2022-09-19 11:21:34,737 INFO: Hpp startup [in /Users/ryancalderone/HPP/HPP copy 3/app/__init__.py:46]
2022-09-19 11:24:12,659 INFO: Hpp startup [in /Users/ryancalderone/HPP/HPP copy 3/app/__init__.py:46]
2022-09-19 12:56:30,234 INFO: Hpp startup [in /Users/ryancalderone/HPP/HPP copy 3/app/__init__.py:46]
2022-09-19 12:58:08,055 INFO: Hpp startup [in /Users/ryancalderone/HPP/HPP/app/__init__.py:46]
2022-09-21 00:10:07,879 INFO: Hpp startup [in /Users/ryancalderone/HPP/HPP/app/__init__.py:46]
2022-09-21 00:12:32,544 INFO: Hpp startup [in /Users/ryancalderone/HPP/HPP/app/__init__.py:46]
2022-09-21 00:13:56,329 INFO: Hpp startup [in /Users/ryancalderone/HPP/HPP/app/__init__.py:46]
2022-09-21 00:14:34,291 INFO: Hpp startup [in /Users/ryancalderone/HPP/HPP/app/__init__.py:46]
2022-09-21 00:15:02,731 ERROR: Exception on /data [POST] [in /Users/ryancalderone/venv/lib/python3.7/site-packages/flask/app.py:1455]
Traceback (most recent call last):
  File "/Users/ryancalderone/venv/lib/python3.7/site-packages/flask/app.py", line 2070, in wsgi_app
    response = self.full_dispatch_request()
  File "/Users/ryancalderone/venv/lib/python3.7/site-packages/flask/app.py", line 1515, in full_dispatch_request
    rv = self.handle_user_exception(e)
  File "/Users/ryancalderone/venv/lib/python3.7/site-packages/flask/app.py", line 1513, in full_dispatch_request
    rv = self.dispatch_request()
  File "/Users/ryancalderone/venv/lib/python3.7/site-packages/flask/app.py", line 1499, in dispatch_request
    return self.ensure_sync(self.view_functions[rule.endpoint])(**req.view_args)
  File "/Users/ryancalderone/venv/lib/python3.7/site-packages/flask_login/utils.py", line 290, in decorated_view
    return current_app.ensure_sync(func)(*args, **kwargs)
  File "/Users/ryancalderone/HPP/HPP/app/routes.py", line 144, in data
    name = form.name.data
AttributeError: 'DataForm' object has no attribute 'name'
2022-09-21 00:40:04,065 INFO: Hpp startup [in /Users/ryancalderone/HPP/HPP/app/__init__.py:46]
2022-09-21 00:40:45,156 INFO: Hpp startup [in /Users/ryancalderone/HPP/HPP/app/__init__.py:46]
2022-09-21 00:40:50,114 ERROR: Exception on /data [GET] [in /Users/ryancalderone/venv/lib/python3.7/site-packages/flask/app.py:1455]
Traceback (most recent call last):
  File "/Users/ryancalderone/venv/lib/python3.7/site-packages/flask/app.py", line 2070, in wsgi_app
    response = self.full_dispatch_request()
  File "/Users/ryancalderone/venv/lib/python3.7/site-packages/flask/app.py", line 1515, in full_dispatch_request
    rv = self.handle_user_exception(e)
  File "/Users/ryancalderone/venv/lib/python3.7/site-packages/flask/app.py", line 1513, in full_dispatch_request
    rv = self.dispatch_request()
  File "/Users/ryancalderone/venv/lib/python3.7/site-packages/flask/app.py", line 1499, in dispatch_request
    return self.ensure_sync(self.view_functions[rule.endpoint])(**req.view_args)
  File "/Users/ryancalderone/venv/lib/python3.7/site-packages/flask_login/utils.py", line 290, in decorated_view
    return current_app.ensure_sync(func)(*args, **kwargs)
  File "/Users/ryancalderone/HPP/HPP/app/routes.py", line 153, in data
    return render_template('dataEntry.html', output = prediction)
  File "/Users/ryancalderone/venv/lib/python3.7/site-packages/flask/templating.py", line 150, in render_template
    ctx.app,
  File "/Users/ryancalderone/venv/lib/python3.7/site-packages/flask/templating.py", line 128, in _render
    rv = template.render(context)
  File "/Users/ryancalderone/venv/lib/python3.7/site-packages/jinja2/environment.py", line 1304, in render
    self.environment.handle_exception()
  File "/Users/ryancalderone/venv/lib/python3.7/site-packages/jinja2/environment.py", line 925, in handle_exception
    raise rewrite_traceback_stack(source=source)
  File "/Users/ryancalderone/HPP/HPP/app/templates/dataEntry.html", line 1, in top-level template code
    {% extends "base.html" %}
  File "/Users/ryancalderone/HPP/HPP/app/templates/base.html", line 52, in top-level template code
    {% endif %} {% endwith %} {% block content %}{% endblock %}
  File "/Users/ryancalderone/HPP/HPP/app/templates/dataEntry.html", line 7, in block 'content'
    {{ form.hidden_tag() }}
  File "/Users/ryancalderone/venv/lib/python3.7/site-packages/jinja2/environment.py", line 474, in getattr
    return getattr(obj, attribute)
jinja2.exceptions.UndefinedError: 'form' is undefined
