2022-09-21 07:26:56,287 ERROR: Exception on /data [GET] [in /Users/ryancalderone/venv/lib/python3.7/site-packages/flask/app.py:1455]
Traceback (most recent call last):
  File "/Users/ryancalderone/venv/lib/python3.7/site-packages/flask/app.py", line 2070, in wsgi_app
    response = self.full_dispatch_request()
  File "/Users/ryancalderone/venv/lib/python3.7/site-packages/flask/app.py", line 1515, in full_dispatch_request
    rv = self.handle_user_exception(e)
  File "/Users/ryancalderone/venv/lib/python3.7/site-packages/flask/app.py", line 1513, in full_dispatch_request
    rv = self.dispatch_request()
  File "/Users/ryancalderone/venv/lib/python3.7/site-packages/flask/app.py", line 1499, in dispatch_request
    return self.ensure_sync(self.view_functions[rule.endpoint])(**req.view_args)
  File "/Users/ryancalderone/venv/lib/python3.7/site-packages/flask_login/utils.py", line 290, in decorated_view
    return current_app.ensure_sync(func)(*args, **kwargs)
  File "/Users/ryancalderone/HPP/HPP/app/routes.py", line 153, in data
    return render_template('dataEntry.html', output = prediction)
  File "/Users/ryancalderone/venv/lib/python3.7/site-packages/flask/templating.py", line 150, in render_template
    ctx.app,
  File "/Users/ryancalderone/venv/lib/python3.7/site-packages/flask/templating.py", line 128, in _render
    rv = template.render(context)
  File "/Users/ryancalderone/venv/lib/python3.7/site-packages/jinja2/environment.py", line 1304, in render
    self.environment.handle_exception()
  File "/Users/ryancalderone/venv/lib/python3.7/site-packages/jinja2/environment.py", line 925, in handle_exception
    raise rewrite_traceback_stack(source=source)
  File "/Users/ryancalderone/HPP/HPP/app/templates/dataEntry.html", line 1, in top-level template code
    {% extends "base.html" %}
  File "/Users/ryancalderone/HPP/HPP/app/templates/base.html", line 52, in top-level template code
    {% endif %} {% endwith %} {% block content %}{% endblock %}
  File "/Users/ryancalderone/HPP/HPP/app/templates/dataEntry.html", line 7, in block 'content'
    {{ form.hidden_tag() }}
  File "/Users/ryancalderone/venv/lib/python3.7/site-packages/jinja2/environment.py", line 474, in getattr
    return getattr(obj, attribute)
jinja2.exceptions.UndefinedError: 'form' is undefined
2022-09-21 08:24:11,795 INFO: Hpp startup [in /Users/ryancalderone/HPP/HPP/app/__init__.py:46]
2022-09-21 08:24:21,095 ERROR: Exception on /data [GET] [in /Users/ryancalderone/venv/lib/python3.7/site-packages/flask/app.py:1455]
Traceback (most recent call last):
  File "/Users/ryancalderone/venv/lib/python3.7/site-packages/flask/app.py", line 2070, in wsgi_app
    response = self.full_dispatch_request()
  File "/Users/ryancalderone/venv/lib/python3.7/site-packages/flask/app.py", line 1515, in full_dispatch_request
    rv = self.handle_user_exception(e)
  File "/Users/ryancalderone/venv/lib/python3.7/site-packages/flask/app.py", line 1513, in full_dispatch_request
    rv = self.dispatch_request()
  File "/Users/ryancalderone/venv/lib/python3.7/site-packages/flask/app.py", line 1499, in dispatch_request
    return self.ensure_sync(self.view_functions[rule.endpoint])(**req.view_args)
  File "/Users/ryancalderone/venv/lib/python3.7/site-packages/flask_login/utils.py", line 290, in decorated_view
    return current_app.ensure_sync(func)(*args, **kwargs)
  File "/Users/ryancalderone/HPP/HPP/app/routes.py", line 155, in data
    return render_template('dataEntry.html', output = prediction)
  File "/Users/ryancalderone/venv/lib/python3.7/site-packages/flask/templating.py", line 150, in render_template
    ctx.app,
  File "/Users/ryancalderone/venv/lib/python3.7/site-packages/flask/templating.py", line 128, in _render
    rv = template.render(context)
  File "/Users/ryancalderone/venv/lib/python3.7/site-packages/jinja2/environment.py", line 1304, in render
    self.environment.handle_exception()
  File "/Users/ryancalderone/venv/lib/python3.7/site-packages/jinja2/environment.py", line 925, in handle_exception
    raise rewrite_traceback_stack(source=source)
  File "/Users/ryancalderone/HPP/HPP/app/templates/dataEntry.html", line 1, in top-level template code
    {% extends "base.html" %}
  File "/Users/ryancalderone/HPP/HPP/app/templates/base.html", line 52, in top-level template code
    {% endif %} {% endwith %} {% block content %}{% endblock %}
  File "/Users/ryancalderone/HPP/HPP/app/templates/dataEntry.html", line 7, in block 'content'
    {{ form.hidden_tag() }}
  File "/Users/ryancalderone/venv/lib/python3.7/site-packages/jinja2/environment.py", line 474, in getattr
    return getattr(obj, attribute)
jinja2.exceptions.UndefinedError: 'form' is undefined
2022-09-21 08:24:47,842 ERROR: Exception on /data [GET] [in /Users/ryancalderone/venv/lib/python3.7/site-packages/flask/app.py:1455]
Traceback (most recent call last):
  File "/Users/ryancalderone/venv/lib/python3.7/site-packages/flask/app.py", line 2070, in wsgi_app
    response = self.full_dispatch_request()
  File "/Users/ryancalderone/venv/lib/python3.7/site-packages/flask/app.py", line 1515, in full_dispatch_request
    rv = self.handle_user_exception(e)
  File "/Users/ryancalderone/venv/lib/python3.7/site-packages/flask/app.py", line 1513, in full_dispatch_request
    rv = self.dispatch_request()
  File "/Users/ryancalderone/venv/lib/python3.7/site-packages/flask/app.py", line 1499, in dispatch_request
    return self.ensure_sync(self.view_functions[rule.endpoint])(**req.view_args)
  File "/Users/ryancalderone/venv/lib/python3.7/site-packages/flask_login/utils.py", line 290, in decorated_view
    return current_app.ensure_sync(func)(*args, **kwargs)
  File "/Users/ryancalderone/HPP/HPP/app/routes.py", line 155, in data
    return render_template('dataEntry.html', output = prediction)
  File "/Users/ryancalderone/venv/lib/python3.7/site-packages/flask/templating.py", line 150, in render_template
    ctx.app,
  File "/Users/ryancalderone/venv/lib/python3.7/site-packages/flask/templating.py", line 128, in _render
    rv = template.render(context)
  File "/Users/ryancalderone/venv/lib/python3.7/site-packages/jinja2/environment.py", line 1304, in render
    self.environment.handle_exception()
  File "/Users/ryancalderone/venv/lib/python3.7/site-packages/jinja2/environment.py", line 925, in handle_exception
    raise rewrite_traceback_stack(source=source)
  File "/Users/ryancalderone/HPP/HPP/app/templates/dataEntry.html", line 1, in top-level template code
    {% extends "base.html" %}
  File "/Users/ryancalderone/HPP/HPP/app/templates/base.html", line 52, in top-level template code
    {% endif %} {% endwith %} {% block content %}{% endblock %}
  File "/Users/ryancalderone/HPP/HPP/app/templates/dataEntry.html", line 7, in block 'content'
    {{ form.hidden_tag() }}
  File "/Users/ryancalderone/venv/lib/python3.7/site-packages/jinja2/environment.py", line 474, in getattr
    return getattr(obj, attribute)
jinja2.exceptions.UndefinedError: 'form' is undefined
2022-09-21 08:26:17,609 INFO: Hpp startup [in /Users/ryancalderone/HPP/HPP/app/__init__.py:46]
2022-09-21 08:26:23,343 ERROR: Exception on /data [GET] [in /Users/ryancalderone/venv/lib/python3.7/site-packages/flask/app.py:1455]
Traceback (most recent call last):
  File "/Users/ryancalderone/venv/lib/python3.7/site-packages/flask/app.py", line 2070, in wsgi_app
    response = self.full_dispatch_request()
  File "/Users/ryancalderone/venv/lib/python3.7/site-packages/flask/app.py", line 1515, in full_dispatch_request
    rv = self.handle_user_exception(e)
  File "/Users/ryancalderone/venv/lib/python3.7/site-packages/flask/app.py", line 1513, in full_dispatch_request
    rv = self.dispatch_request()
  File "/Users/ryancalderone/venv/lib/python3.7/site-packages/flask/app.py", line 1499, in dispatch_request
    return self.ensure_sync(self.view_functions[rule.endpoint])(**req.view_args)
  File "/Users/ryancalderone/venv/lib/python3.7/site-packages/flask_login/utils.py", line 290, in decorated_view
    return current_app.ensure_sync(func)(*args, **kwargs)
  File "/Users/ryancalderone/HPP/HPP/app/routes.py", line 155, in data
    return render_template('dataEntry.html', output = prediction)
  File "/Users/ryancalderone/venv/lib/python3.7/site-packages/flask/templating.py", line 150, in render_template
    ctx.app,
  File "/Users/ryancalderone/venv/lib/python3.7/site-packages/flask/templating.py", line 128, in _render
    rv = template.render(context)
  File "/Users/ryancalderone/venv/lib/python3.7/site-packages/jinja2/environment.py", line 1304, in render
    self.environment.handle_exception()
  File "/Users/ryancalderone/venv/lib/python3.7/site-packages/jinja2/environment.py", line 925, in handle_exception
    raise rewrite_traceback_stack(source=source)
  File "/Users/ryancalderone/HPP/HPP/app/templates/dataEntry.html", line 1, in top-level template code
    {% extends "base.html" %}
  File "/Users/ryancalderone/HPP/HPP/app/templates/base.html", line 52, in top-level template code
    {% endif %} {% endwith %} {% block content %}{% endblock %}
  File "/Users/ryancalderone/HPP/HPP/app/templates/dataEntry.html", line 7, in block 'content'
    {{ form.hidden_tag() }}
  File "/Users/ryancalderone/venv/lib/python3.7/site-packages/jinja2/environment.py", line 474, in getattr
    return getattr(obj, attribute)
jinja2.exceptions.UndefinedError: 'form' is undefined
2022-09-21 08:27:44,557 INFO: Hpp startup [in /Users/ryancalderone/HPP/HPP/app/__init__.py:46]
2022-09-21 08:28:41,467 INFO: Hpp startup [in /Users/ryancalderone/HPP/HPP/app/__init__.py:46]
2022-09-21 08:29:05,323 INFO: Hpp startup [in /Users/ryancalderone/HPP/HPP/app/__init__.py:46]
