2022-09-21 08:40:28,440 ERROR: Exception on /data [GET] [in /Users/ryancalderone/venv/lib/python3.7/site-packages/flask/app.py:1455]
Traceback (most recent call last):
  File "/Users/ryancalderone/venv/lib/python3.7/site-packages/flask/app.py", line 2070, in wsgi_app
    response = self.full_dispatch_request()
  File "/Users/ryancalderone/venv/lib/python3.7/site-packages/flask/app.py", line 1515, in full_dispatch_request
    rv = self.handle_user_exception(e)
  File "/Users/ryancalderone/venv/lib/python3.7/site-packages/flask/app.py", line 1513, in full_dispatch_request
    rv = self.dispatch_request()
  File "/Users/ryancalderone/venv/lib/python3.7/site-packages/flask/app.py", line 1499, in dispatch_request
    return self.ensure_sync(self.view_functions[rule.endpoint])(**req.view_args)
  File "/Users/ryancalderone/venv/lib/python3.7/site-packages/flask_login/utils.py", line 290, in decorated_view
    return current_app.ensure_sync(func)(*args, **kwargs)
  File "/Users/ryancalderone/HPP/HPP/app/routes.py", line 155, in data
    return render_template('dataEntry.html', form=form)
NameError: name 'form' is not defined
2022-09-21 08:42:24,137 INFO: Hpp startup [in /Users/ryancalderone/HPP/HPP/app/__init__.py:46]
2022-09-21 08:42:27,449 ERROR: Exception on /data [GET] [in /Users/ryancalderone/venv/lib/python3.7/site-packages/flask/app.py:1455]
Traceback (most recent call last):
  File "/Users/ryancalderone/venv/lib/python3.7/site-packages/flask/app.py", line 2070, in wsgi_app
    response = self.full_dispatch_request()
  File "/Users/ryancalderone/venv/lib/python3.7/site-packages/flask/app.py", line 1515, in full_dispatch_request
    rv = self.handle_user_exception(e)
  File "/Users/ryancalderone/venv/lib/python3.7/site-packages/flask/app.py", line 1513, in full_dispatch_request
    rv = self.dispatch_request()
  File "/Users/ryancalderone/venv/lib/python3.7/site-packages/flask/app.py", line 1499, in dispatch_request
    return self.ensure_sync(self.view_functions[rule.endpoint])(**req.view_args)
  File "/Users/ryancalderone/venv/lib/python3.7/site-packages/flask_login/utils.py", line 290, in decorated_view
    return current_app.ensure_sync(func)(*args, **kwargs)
  File "/Users/ryancalderone/HPP/HPP/app/routes.py", line 155, in data
    return render_template('dataEntry.html', form=FlaskForms, output = prediction)
NameError: name 'FlaskForms' is not defined
2022-09-21 08:46:43,461 INFO: Hpp startup [in /Users/ryancalderone/HPP/HPP/app/__init__.py:46]
2022-09-21 08:46:47,776 ERROR: Exception on /data [GET] [in /Users/ryancalderone/venv/lib/python3.7/site-packages/flask/app.py:1455]
Traceback (most recent call last):
  File "/Users/ryancalderone/venv/lib/python3.7/site-packages/flask/app.py", line 2070, in wsgi_app
    response = self.full_dispatch_request()
  File "/Users/ryancalderone/venv/lib/python3.7/site-packages/flask/app.py", line 1515, in full_dispatch_request
    rv = self.handle_user_exception(e)
  File "/Users/ryancalderone/venv/lib/python3.7/site-packages/flask/app.py", line 1513, in full_dispatch_request
    rv = self.dispatch_request()
  File "/Users/ryancalderone/venv/lib/python3.7/site-packages/flask/app.py", line 1499, in dispatch_request
    return self.ensure_sync(self.view_functions[rule.endpoint])(**req.view_args)
  File "/Users/ryancalderone/venv/lib/python3.7/site-packages/flask_login/utils.py", line 290, in decorated_view
    return current_app.ensure_sync(func)(*args, **kwargs)
  File "/Users/ryancalderone/HPP/HPP/app/routes.py", line 155, in data
    return render_template('dataEntry.html', form=form, output = prediction)
NameError: name 'form' is not defined
2022-09-21 08:47:27,513 INFO: Hpp startup [in /Users/ryancalderone/HPP/HPP/app/__init__.py:46]
2022-09-21 08:47:32,565 ERROR: Exception on /data [GET] [in /Users/ryancalderone/venv/lib/python3.7/site-packages/flask/app.py:1455]
Traceback (most recent call last):
  File "/Users/ryancalderone/venv/lib/python3.7/site-packages/flask/app.py", line 2070, in wsgi_app
    response = self.full_dispatch_request()
  File "/Users/ryancalderone/venv/lib/python3.7/site-packages/flask/app.py", line 1515, in full_dispatch_request
    rv = self.handle_user_exception(e)
  File "/Users/ryancalderone/venv/lib/python3.7/site-packages/flask/app.py", line 1513, in full_dispatch_request
    rv = self.dispatch_request()
  File "/Users/ryancalderone/venv/lib/python3.7/site-packages/flask/app.py", line 1499, in dispatch_request
    return self.ensure_sync(self.view_functions[rule.endpoint])(**req.view_args)
  File "/Users/ryancalderone/venv/lib/python3.7/site-packages/flask_login/utils.py", line 290, in decorated_view
    return current_app.ensure_sync(func)(*args, **kwargs)
  File "/Users/ryancalderone/HPP/HPP/app/routes.py", line 155, in data
    return render_template('dataEntry.html', form=form, output = prediction)
NameError: name 'form' is not defined
2022-09-21 08:50:07,391 INFO: Hpp startup [in /Users/ryancalderone/HPP/HPP/app/__init__.py:46]
2022-09-21 08:50:13,665 ERROR: Exception on /data [GET] [in /Users/ryancalderone/venv/lib/python3.7/site-packages/flask/app.py:1455]
Traceback (most recent call last):
  File "/Users/ryancalderone/venv/lib/python3.7/site-packages/flask/app.py", line 2070, in wsgi_app
    response = self.full_dispatch_request()
  File "/Users/ryancalderone/venv/lib/python3.7/site-packages/flask/app.py", line 1515, in full_dispatch_request
    rv = self.handle_user_exception(e)
  File "/Users/ryancalderone/venv/lib/python3.7/site-packages/flask/app.py", line 1513, in full_dispatch_request
    rv = self.dispatch_request()
  File "/Users/ryancalderone/venv/lib/python3.7/site-packages/flask/app.py", line 1499, in dispatch_request
    return self.ensure_sync(self.view_functions[rule.endpoint])(**req.view_args)
  File "/Users/ryancalderone/venv/lib/python3.7/site-packages/flask_login/utils.py", line 290, in decorated_view
    return current_app.ensure_sync(func)(*args, **kwargs)
  File "/Users/ryancalderone/HPP/HPP/app/routes.py", line 155, in data
    return render_template('dataEntry.html', form=form, output = prediction)
NameError: name 'form' is not defined
2022-09-21 08:50:39,260 INFO: Hpp startup [in /Users/ryancalderone/HPP/HPP/app/__init__.py:46]
2022-09-21 08:50:42,639 ERROR: Exception on /data [GET] [in /Users/ryancalderone/venv/lib/python3.7/site-packages/flask/app.py:1455]
Traceback (most recent call last):
  File "/Users/ryancalderone/venv/lib/python3.7/site-packages/flask/app.py", line 2070, in wsgi_app
    response = self.full_dispatch_request()
  File "/Users/ryancalderone/venv/lib/python3.7/site-packages/flask/app.py", line 1515, in full_dispatch_request
    rv = self.handle_user_exception(e)
  File "/Users/ryancalderone/venv/lib/python3.7/site-packages/flask/app.py", line 1513, in full_dispatch_request
    rv = self.dispatch_request()
  File "/Users/ryancalderone/venv/lib/python3.7/site-packages/flask/app.py", line 1499, in dispatch_request
    return self.ensure_sync(self.view_functions[rule.endpoint])(**req.view_args)
  File "/Users/ryancalderone/venv/lib/python3.7/site-packages/flask_login/utils.py", line 290, in decorated_view
    return current_app.ensure_sync(func)(*args, **kwargs)
  File "/Users/ryancalderone/HPP/HPP/app/routes.py", line 155, in data
    return render_template('dataEntry.html', form=form, output=prediction)
NameError: name 'form' is not defined
2022-09-21 08:52:39,093 INFO: Hpp startup [in /Users/ryancalderone/HPP/HPP/app/__init__.py:46]
2022-09-21 08:52:43,298 ERROR: Exception on /data [GET] [in /Users/ryancalderone/venv/lib/python3.7/site-packages/flask/app.py:1455]
Traceback (most recent call last):
  File "/Users/ryancalderone/venv/lib/python3.7/site-packages/flask/app.py", line 2070, in wsgi_app
    response = self.full_dispatch_request()
  File "/Users/ryancalderone/venv/lib/python3.7/site-packages/flask/app.py", line 1515, in full_dispatch_request
    rv = self.handle_user_exception(e)
  File "/Users/ryancalderone/venv/lib/python3.7/site-packages/flask/app.py", line 1513, in full_dispatch_request
    rv = self.dispatch_request()
  File "/Users/ryancalderone/venv/lib/python3.7/site-packages/flask/app.py", line 1499, in dispatch_request
    return self.ensure_sync(self.view_functions[rule.endpoint])(**req.view_args)
  File "/Users/ryancalderone/venv/lib/python3.7/site-packages/flask_login/utils.py", line 290, in decorated_view
    return current_app.ensure_sync(func)(*args, **kwargs)
  File "/Users/ryancalderone/HPP/HPP/app/routes.py", line 156, in data
    return render_template('dataEntry.html', form=form, output=prediction)
NameError: name 'form' is not defined
2022-09-21 08:54:04,203 INFO: Hpp startup [in /Users/ryancalderone/HPP/HPP/app/__init__.py:46]
2022-09-21 08:54:08,817 ERROR: Exception on /data [GET] [in /Users/ryancalderone/venv/lib/python3.7/site-packages/flask/app.py:1455]
Traceback (most recent call last):
  File "/Users/ryancalderone/venv/lib/python3.7/site-packages/flask/app.py", line 2070, in wsgi_app
    response = self.full_dispatch_request()
  File "/Users/ryancalderone/venv/lib/python3.7/site-packages/flask/app.py", line 1515, in full_dispatch_request
    rv = self.handle_user_exception(e)
  File "/Users/ryancalderone/venv/lib/python3.7/site-packages/flask/app.py", line 1513, in full_dispatch_request
    rv = self.dispatch_request()
  File "/Users/ryancalderone/venv/lib/python3.7/site-packages/flask/app.py", line 1499, in dispatch_request
    return self.ensure_sync(self.view_functions[rule.endpoint])(**req.view_args)
  File "/Users/ryancalderone/venv/lib/python3.7/site-packages/flask_login/utils.py", line 290, in decorated_view
    return current_app.ensure_sync(func)(*args, **kwargs)
  File "/Users/ryancalderone/HPP/HPP/app/routes.py", line 158, in data
    form.name.data = ''
AttributeError: 'DataForm' object has no attribute 'name'
2022-09-21 08:54:25,861 INFO: Hpp startup [in /Users/ryancalderone/HPP/HPP/app/__init__.py:46]
